Workbook

Sheet Marketing_df1
B1: ID | C1: Year_Birth | D1: Education | E1: Marital_Status | F1: Income | G1: Kidhome | H1: Teenhome | I1: Dt_Customer | J1: Recency
A2: 0 | B2: 5524 | C2: 1957 | D2: Graduation | E2: Single | F2: 58138 | G2: 0 | H2: 0 | I2: 41156 | J2: 58
A3: 1 | B3: 2174 | C3: 1954 | D3: Graduation | E3: Single | F3: 46344 | G3: 1 | H3: 1 | I3: 41706 | J3: 38
A4: 2 | B4: 4141 | C4: 1965 | D4: Graduation | E4: Together | F4: 71613 | G4: 0 | H4: 0 | I4: 41507 | J4: 26
A5: 3 | B5: 6182 | C5: 1984 | D5: Graduation | E5: Together | F5: 26646 | G5: 1 | H5: 0 | I5: 41680 | J5: 26
A6: 4 | B6: 5324 | C6: 1981 | D6: PhD | E6: Married | F6: 58293 | G6: 1 | H6: 0 | I6: 41658 | J6: 94
A7: 5 | B7: 7446 | C7: 1967 | D7: Master | E7: Together | F7: 62513 | G7: 0 | H7: 1 | I7: 41526 | J7: 16
A8: 6 | B8: 965 | C8: 1971 | D8: Graduation | E8: Divorced | F8: 55635 | G8: 0 | H8: 1 | I8: 41226 | J8: 34
A9: 7 | B9: 6177 | C9: 1985 | D9: PhD | E9: Married | F9: 33454 | G9: 1 | H9: 0 | I9: 41402 | J9: 32
A10: 8 | B10: 4855 | C10: 1974 | D10: PhD | E10: Together | F10: 30351 | G10: 1 | H10: 0 | I10: 41431 | J10: 19
A11: 9 | B11: 5899 | C11: 1950 | D11: PhD | E11: Together | F11: 5648 | G11: 1 | H11: 1 | I11: 41711 | J11: 68
A12: 10 | B12: 1994 | C12: 1983 | D12: Graduation | E12: Married | G12: 1 | H12: 0 | I12: 41593 | J12: 11
A13: 11 | B13: 387 | C13: 1976 | D13: Basic | E13: Married | F13: 7500 | G13: 0 | H13: 0 | I13: 41226 | J13: 59
A14: 12 | B14: 2125 | C14: 1959 | D14: Graduation | E14: Divorced | F14: 63033 | G14: 0 | H14: 0 | I14: 41593 | J14: 82
A15: 13 | B15: 8180 | C15: 1952 | D15: Master | E15: Divorced | F15: 59354 | G15: 1 | H15: 1 | I15: 41593 | J15: 53
A16: 14 | B16: 2569 | C16: 1987 | D16: Graduation | E16: Married | F16: 17323 | G16: 0 | H16: 0 | I16: 41192 | J16: 38
A17: 15 | B17: 2114 | C17: 1946 | D17: PhD | E17: Single | F17: 82800 | G17: 0 | H17: 0 | I17: 41237 | J17: 23
A18: 16 | B18: 9736 | C18: 1980 | D18: Graduation | E18: Married | F18: 41850 | G18: 1 | H18: 1 | I18: 41267 | J18: 51
A19: 17 | B19: 4939 | C19: 1946 | D19: Graduation | E19: Together | F19: 37760 | G19: 0 | H19: 0 | I19: 41152 | J19: 20
A20: 18 | B20: 6565 | C20: 1949 | D20: Master | E20: Married | F20: 76995 | G20: 0 | H20: 1 | I20: 41361 | J20: 91
A21: 19 | B21: 2278 | C21: 1985 | D21: 2n Cycle | E21: Single | F21: 33812 | G21: 1 | H21: 0 | I21: 41216 | J21: 86
A22: 20 | B22: 9360 | C22: 1982 | D22: Graduation | E22: Married | F22: 37040 | G22: 0 | H22: 0 | I22: 41129 | J22: 41
A23: 21 | B23: 5376 | C23: 1979 | D23: Graduation | E23: Married | F23: 2447 | G23: 1 | H23: 0 | I23: 41280 | J23: 42
A24: 22 | B24: 1993 | C24: 1949 | D24: PhD | E24: Married | F24: 58607 | G24: 0 | H24: 1 | I24: 41266 | J24: 63
... A28: 26 | B28: 2404 | C28: 1976 | D28: Graduation | E28: Married | F28: 53359 | G28: 1 | H28: 1 | I28: 41421 | J28: 4
A29: 27 | B29: 5255 | C29: 1986 | D29: Graduation | E29: Single | G29: 1 | H29: 0 | I29: 41325 | J29: 19
A30: 28 | B30: 9422 | C30: 1989 | D30: Graduation | E30: Married | F30: 38360 | G30: 1 | H30: 0 | I30: 41425 | J30: 26
A31: 29 | B31: 1966 | C31: 1965 | D31: PhD | E31: Married | F31: 84618 | G31: 0 | H31: 0 | I31: 41600 | J31: 96
A32: 30 | B32: 6864 | C32: 1989 | D32: Master | E32: Divorced | F32: 10979 | G32: 0 | H32: 0 | I32: 41781 | J32: 34
A33: 31 | B33: 3033 | C33: 1963 | D33: Master | E33: Together | F33: 38620 | G33: 0 | H33: 0 | I33: 41405 | J33: 56
A34: 32 | B34: 5710 | C34: 1970 | D34: Graduation | E34: Together | F34: 40548 | G34: 0 | H34: 1 | I34: 41192 | J34: 31
A35: 33 | B35: 7373 | C35: 1952 | D35: PhD | E35: Divorced | F35: 46610 | G35: 0 | H35: 2 | I35: 41211 | J35: 8
A36: 34 | B36: 8755 | C36: 1946 | D36: Master | E36: Married | F36: 68657 | G36: 0 | H36: 0 | I36: 41325 | J36: 4
A37: 35 | B37: 10738 | C37: 1951 | D37: Master | E37: Single | F37: 49389 | G37: 1 | H37: 1 | I37: 41515 | J37: 55
A38: 36 | B38: 4339 | C38: 1970 | D38: PhD | E38: Married | F38: 67353 | G38: 0 | H38: 1 | I38: 41639 | J38: 37
A39: 37 | B39: 10755 | C39: 1976 | D39: 2n Cycle | E39: Married | F39: 23718 | G39: 1 | H39: 0 | I39: 41519 | J39: 76
A40: 38 | B40: 8595 | C40: 1973 | D40: Graduation | E40: Widow | F40: 42429 | G40: 0 | H40: 1 | I40: 41681 | J40: 99
A41: 39 | B41: 2968 | C41: 1943 | D41: PhD | E41: Divorced | F41: 48948 | G41: 0 | H41: 0 | I41: 41306 | J41: 53
... A44: 42 | B44: 8430 | C44: 1957 | D44: Graduation | E44: Together | F44: 21994 | G44: 0 | H44: 1 | I44: 41267 | J44: 4
A45: 43 | B45: 7281 | C45: 1959 | D45: PhD | E45: Single | G45: 0 | H45: 0 | I45: 41583 | J45: 80
...

Sheet Marketing_df2
B1: ID | C1: MntFruits | D1: MntSweetProducts | E1: NumWebPurchases | F1: NumStorePurchases
A2: 1898 | B2: 4619 | C2: 2 | D2: 262 | E2: 27 | F2: 0
A3: 27 | B3: 5255 | C3: 1 | D3: 263 | E3: 27 | F3: 0
A4: 1975 | B4: 10311 | C4: 4 | D4: 4 | E4: 25 | F4: 0
A5: 1806 | B5: 6237 | C5: 4 | D5: 2 | E5: 23 | F5: 1
A6: 336 | B6: 7381 | C6: 153 | D6: 97 | E6: 11 | F6: 6
A7: 1924 | B7: 7966 | C7: 137 | D7: 22 | E7: 11 | F7: 11
A8: 681 | B8: 4910 | C8: 134 | D8: 134 | E8: 11 | F8: 13
A9: 2013 | B9: 1951 | C9: 122 | D9: 129 | E9: 11 | F9: 8
A10: 1507 | B10: 7706 | C10: 104 | D10: 151 | E10: 11 | F10: 5
A11: 924 | B11: 8931 | C11: 99 | D11: 149 | E11: 11 | F11: 10
A12: 767 | B12: 1911 | C12: 97 | D12: 133 | E12: 11 | F12: 12
A13: 1488 | B13: 9743 | C13: 89 | D13: 35 | E13: 11 | F13: 8
... A2241: 2019 | B2241: 2375 | C2241: 0 | D2241: 3 | E2241: 0 | F2241: 3

Sheet Merged_df1&2
A1: Sl No. | B1: ID | C1: Year_Birth | D1: Education | E1: Marital_Status | F1: Income | G1: Kidhome | H1: Teenhome | I1: Total_Kidshome | J1: Dt_Customer | K1: Recency | L1: MntFruits | M1: MntSweetProducts | N1: NumWebPurchases | O1: NumStorePurchases
A2: 0 | B2: 5524 | C2: 1957 | D2: Graduation | E2: Single | F2: 58138 | G2: 0 | H2: 0 | I2: =G2+H2 -> 0 | J2: 41156 | K2: 58 | L2: =VLOOKUP(A2,Marketing_df2!$A$1:$F$2241,3,FALSE) -> 88 | M2: =VLOOKUP(A2,Marketing_df2!$A$1:$F$2241,4,FALSE) -> 88 | N2: =VLOOKUP(A2,Marketing_df2!$A$1:$F$2241,5,FALSE) -> 8 | O2: =VLOOKUP(A2,Marketing_df2!$A$1:$F$2241,6,FALSE) -> 4
A3: 1 | B3: 2174 | C3: 1954 | D3: Graduation | E3: Single | F3: 46344 | G3: 1 | H3: 1 | I3: =G3+H3 -> 2 | J3: 41706 | K3: 38 | L3: =VLOOKUP(A3,Marketing_df2!$A$1:$F$2241,3,FALSE) -> 1 | M3: =VLOOKUP(A3,Marketing_df2!$A$1:$F$2241,4,FALSE) -> 1 | N3: =VLOOKUP(A3,Marketing_df2!$A$1:$F$2241,5,FALSE) -> 1 | O3: =VLOOKUP(A3,Marketing_df2!$A$1:$F$2241,6,FALSE) -> 2
A4: 2 | B4: 4141 | C4: 1965 | D4: Graduation | E4: Together | F4: 71613 | G4: 0 | H4: 0 | I4: =G4+H4 -> 0 | J4: 41507 | K4: 26 | L4: =VLOOKUP(A4,Marketing_df2!$A$1:$F$2241,3,FALSE) -> 49 | M4: =VLOOKUP(A4,Marketing_df2!$A$1:$F$2241,4,FALSE) -> 21 | N4: =VLOOKUP(A4,Marketing_df2!$A$1:$F$2241,5,FALSE) -> 8 | O4: =VLOOKUP(A4,Marketing_df2!$A$1:$F$2241,6,FALSE) -> 10
A5: 3 | B5: 6182 | C5: 1984 | D5: Graduation | E5: Together | F5: 26646 | G5: 1 | H5: 0 | I5: =G5+H5 -> 1 | J5: 41680 | K5: 26 | L5: =VLOOKUP(A5,Marketing_df2!$A$1:$F$2241,3,FALSE) -> 4 | M5: =VLOOKUP(A5,Marketing_df2!$A$1:$F$2241,4,FALSE) -> 3 | N5: =VLOOKUP(A5,Marketing_df2!$A$1:$F$2241,5,FALSE) -> 2 | O5: =VLOOKUP(A5,Marketing_df2!$A$1:$F$2241,6,FALSE) -> 4
A6: 4 | B6: 5324 | C6: 1981 | D6: PhD | E6: Married | F6: 58293 | G6: 1 | H6: 0 | I6: =G6+H6 -> 1 | J6: 41658 | K6: 94 | L6: =VLOOKUP(A6,Marketing_df2!$A$1:$F$2241,3,FALSE) -> 43 | M6: =VLOOKUP(A6,Marketing_df2!$A$1:$F$2241,4,FALSE) -> 27 | N6: =VLOOKUP(A6,Marketing_df2!$A$1:$F$2241,5,FALSE) -> 5 | O6: =VLOOKUP(A6,Marketing_df2!$A$1:$F$2241,6,FALSE) -> 6
A7: 5 | B7: 7446 | C7: 1967 | D7: Master | E7: Together | F7: 62513 | G7: 0 | H7: 1 | I7: =G7+H7 -> 1 | J7: 41526 | K7: 16 | L7: =VLOOKUP(A7,Marketing_df2!$A$1:$F$2241,3,FALSE) -> 42 | M7: =VLOOKUP(A7,Marketing_df2!$A$1:$F$2241,4,FALSE) -> 42 | N7: =VLOOKUP(A7,Marketing_df2!$A$1:$F$2241,5,FALSE) -> 6 | O7: =VLOOKUP(A7,Marketing_df2!$A$1:$F$2241,6,FALSE) -> 10
A8: 6 | B8: 965 | C8: 1971 | D8: Graduation | E8: Divorced | F8: 55635 | G8: 0 | H8: 1 | I8: =G8+H8 -> 1 | J8: 41226 | K8: 34 | L8: =VLOOKUP(A8,Marketing_df2!$A$1:$F$2241,3,FALSE) -> 65 | M8: =VLOOKUP(A8,Marketing_df2!$A$1:$F$2241,4,FALSE) -> 49 | N8: =VLOOKUP(A8,Marketing_df2!$A$1:$F$2241,5,FALSE) -> 7 | O8: =VLOOKUP(A8,Marketing_df2!$A$1:$F$2241,6,FALSE) -> 7
A9: 7 | B9: 6177 | C9: 1985 | D9: PhD | E9: Married | F9: 33454 | G9: 1 | H9: 0 | I9: =G9+H9 -> 1 | J9: 41402 | K9: 32 | L9: =VLOOKUP(A9,Marketing_df2!$A$1:$F$2241,3,FALSE) -> 10 | M9: =VLOOKUP(A9,Marketing_df2!$A$1:$F$2241,4,FALSE) -> 1 | N9: =VLOOKUP(A9,Marketing_df2!$A$1:$F$2241,5,FALSE) -> 4 | O9: =VLOOKUP(A9,Marketing_df2!$A$1:$F$2241,6,FALSE) -> 4
A10: 8 | B10: 4855 | C10: 1974 | D10: PhD | E10: Together | F10: 30351 | G10: 1 | H10: 0 | I10: =G10+H10 -> 1 | J10: 41431 | K10: 19 | L10: =VLOOKUP(A10,Marketing_df2!$A$1:$F$2241,3,FALSE) -> 0 | M10: =VLOOKUP(A10,Marketing_df2!$A$1:$F$2241,4,FALSE) -> 3 | N10: =VLOOKUP(A10,Marketing_df2!$A$1:$F$2241,5,FALSE) -> 3 | O10: =VLOOKUP(A10,Marketing_df2!$A$1:$F$2241,6,FALSE) -> 2
A11: 9 | B11: 5899 | C11: 1950 | D11: PhD | E11: Together | F11: 5648 | G11: 1 | H11: 1 | I11: =G11+H11 -> 2 | J11: 41711 | K11: 68 | L11: =VLOOKUP(A11,Marketing_df2!$A$1:$F$2241,3,FALSE) -> 0 | M11: =VLOOKUP(A11,Marketing_df2!$A$1:$F$2241,4,FALSE) -> 1 | N11: =VLOOKUP(A11,Marketing_df2!$A$1:$F$2241,5,FALSE) -> 1 | O11: =VLOOKUP(A11,Marketing_df2!$A$1:$F$2241,6,FALSE) -> 0
A12: 10 | B12: 1994 | C12: 1983 | D12: Graduation | E12: Married | G12: 1 | H12: 0 | I12: =G12+H12 -> 1 | J12: 41593 | K12: 11 | L12: =VLOOKUP(A12,Marketing_df2!$A$1:$F$2241,3,FALSE) -> 5 | M12: =VLOOKUP(A12,Marketing_df2!$A$1:$F$2241,4,FALSE) -> 2 | N12: =VLOOKUP(A12,Marketing_df2!$A$1:$F$2241,5,FALSE) -> 1 | O12: =VLOOKUP(A12,Marketing_df2!$A$1:$F$2241,6,FALSE) -> 2
A13: 11 | B13: 387 | C13: 1976 | D13: Basic | E13: Married | F13: 7500 | G13: 0 | H13: 0 | I13: =G13+H13 -> 0 | J13: 41226 | K13: 59 | L13: =VLOOKUP(A13,Marketing_df2!$A$1:$F$2241,3,FALSE) -> 16 | M13: =VLOOKUP(A13,Marketing_df2!$A$1:$F$2241,4,FALSE) -> 1 | N13: =VLOOKUP(A13,Marketing_df2!$A$1:$F$2241,5,FALSE) -> 2 | O13: =VLOOKUP(A13,Marketing_df2!$A$1:$F$2241,6,FALSE) -> 3
A14: 12 | B14: 2125 | C14: 1959 | D14: Graduation | E14: Divorced | F14: 63033 | G14: 0 | H14: 0 | I14: =G14+H14 -> 0 | J14: 41593 | K14: 82 | L14: =VLOOKUP(A14,Marketing_df2!$A$1:$F$2241,3,FALSE) -> 61 | M14: =VLOOKUP(A14,Marketing_df2!$A$1:$F$2241,4,FALSE) -> 112 | N14: =VLOOKUP(A14,Marketing_df2!$A$1:$F$2241,5,FALSE) -> 3 | O14: =VLOOKUP(A14,Marketing_df2!$A$1:$F$2241,6,FALSE) -> 8
A15: 13 | B15: 8180 | C15: 1952 | D15: Master | E15: Divorced | F15: 59354 | G15: 1 | H15: 1 | I15: =G15+H15 -> 2 | J15: 41593 | K15: 53 | L15: =VLOOKUP(A15,Marketing_df2!$A$1:$F$2241,3,FALSE) -> 2 | M15: =VLOOKUP(A15,Marketing_df2!$A$1:$F$2241,4,FALSE) -> 5 | N15: =VLOOKUP(A15,Marketing_df2!$A$1:$F$2241,5,FALSE) -> 6 | O15: =VLOOKUP(A15,Marketing_df2!$A$1:$F$2241,6,FALSE) -> 5
A16: 14 | B16: 2569 | C16: 1987 | D16: Graduation | E16: Married | F16: 17323 | G16: 0 | H16: 0 | I16: =G16+H16 -> 0 | J16: 41192 | K16: 38 | L16: =VLOOKUP(A16,Marketing_df2!$A$1:$F$2241,3,FALSE) -> 14 | M16: =VLOOKUP(A16,Marketing_df2!$A$1:$F$2241,4,FALSE) -> 1 | N16: =VLOOKUP(A16,Marketing_df2!$A$1:$F$2241,5,FALSE) -> 1 | O16: =VLOOKUP(A16,Marketing_df2!$A$1:$F$2241,6,FALSE) -> 3
A17: 15 | B17: 2114 | C17: 1946 | D17: PhD | E17: Single | F17: 82800 | G17: 0 | H17: 0 | I17: =G17+H17 -> 0 | J17: 41237 | K17: 23 | L17: =VLOOKUP(A17,Marketing_df2!$A$1:$F$2241,3,FALSE) -> 22 | M17: =VLOOKUP(A17,Marketing_df2!$A$1:$F$2241,4,FALSE) -> 68 | N17: =VLOOKUP(A17,Marketing_df2!$A$1:$F$2241,5,FALSE) -> 7 | O17: =VLOOKUP(A17,Marketing_df2!$A$1:$F$2241,6,FALSE) -> 12
A18: 16 | B18: 9736 | C18: 1980 | D18: Graduation | E18: Married | F18: 41850 | G18: 1 | H18: 1 | I18: =G18+H18 -> 2 | J18: 41267 | K18: 51 | L18: =VLOOKUP(A18,Marketing_df2!$A$1:$F$2241,3,FALSE) -> 5 | M18: =VLOOKUP(A18,Marketing_df2!$A$1:$F$2241,4,FALSE) -> 13 | N18: =VLOOKUP(A18,Marketing_df2!$A$1:$F$2241,5,FALSE) -> 3 | O18: =VLOOKUP(A18,Marketing_df2!$A$1:$F$2241,6,FALSE) -> 3
A19: 17 | B19: 4939 | C19: 1946 | D19: Graduation | E19: Together | F19: 37760 | G19: 0 | H19: 0 | I19: =G19+H19 -> 0 | J19: 41152 | K19: 20 | L19: =VLOOKUP(A19,Marketing_df2!$A$1:$F$2241,3,FALSE) -> 5 | M19: =VLOOKUP(A19,Marketing_df2!$A$1:$F$2241,4,FALSE) -> 12 | N19: =VLOOKUP(A19,Marketing_df2!$A$1:$F$2241,5,FALSE) -> 4 | O19: =VLOOKUP(A19,Marketing_df2!$A$1:$F$2241,6,FALSE) -> 6
A20: 18 | B20: 6565 | C20: 1949 | D20: Master | E20: Married | F20: 76995 | G20: 0 | H20: 1 | I20: =G20+H20 -> 1 | J20: 41361 | K20: 91 | L20: =VLOOKUP(A20,Marketing_df2!$A$1:$F$2241,3,FALSE) -> 80 | M20: =VLOOKUP(A20,Marketing_df2!$A$1:$F$2241,4,FALSE) -> 16 | N20: =VLOOKUP(A20,Marketing_df2!$A$1:$F$2241,5,FALSE) -> 11 | O20: =VLOOKUP(A20,Marketing_df2!$A$1:$F$2241,6,FALSE) -> 9
A21: 19 | B21: 2278 | C21: 1985 | D21: 2n Cycle | E21: Single | F21: 33812 | G21: 1 | H21: 0 | I21: =G21+H21 -> 1 | J21: 41216 | K21: 86 | L21: =VLOOKUP(A21,Marketing_df2!$A$1:$F$2241,3,FALSE) -> 17 | M21: =VLOOKUP(A21,Marketing_df2!$A$1:$F$2241,4,FALSE) -> 24 | N21: =VLOOKUP(A21,Marketing_df2!$A$1:$F$2241,5,FALSE) -> 2 | O21: =VLOOKUP(A21,Marketing_df2!$A$1:$F$2241,6,FALSE) -> 3
A22: 20 | B22: 9360 | C22: 1982 | D22: Graduation | E22: Married | F22: 37040 | G22: 0 | H22: 0 | I22: =G22+H22 -> 0 | J22: 41129 | K22: 41 | L22: =VLOOKUP(A22,Marketing_df2!$A$1:$F$2241,3,FALSE) -> 2 | M22: =VLOOKUP(A22,Marketing_df2!$A$1:$F$2241,4,FALSE) -> 38 | N22: =VLOOKUP(A22,Marketing_df2!$A$1:$F$2241,5,FALSE) -> 4 | O22: =VLOOKUP(A22,Marketing_df2!$A$1:$F$2241,6,FALSE) -> 5
A23: 21 | B23: 5376 | C23: 1979 | D23: Graduation | E23: Married | F23: 2447 | G23: 1 | H23: 0 | I23: =G23+H23 -> 1 | J23: 41280 | K23: 42 | L23: =VLOOKUP(A23,Marketing_df2!$A$1:$F$2241,3,FALSE) -> 1 | M23: =VLOOKUP(A23,Marketing_df2!$A$1:$F$2241,4,FALSE) -> 1 | N23: =VLOOKUP(A23,Marketing_df2!$A$1:$F$2241,5,FALSE) -> 0 | O23: =VLOOKUP(A23,Marketing_df2!$A$1:$F$2241,6,FALSE) -> 0
A24: 22 | B24: 1993 | C24: 1949 | D24: PhD | E24: Married | F24: 58607 | G24: 0 | H24: 1 | I24: =G24+H24 -> 1 | J24: 41266 | K24: 63 | L24: =VLOOKUP(A24,Marketing_df2!$A$1:$F$2241,3,FALSE) -> 0 | M24: =VLOOKUP(A24,Marketing_df2!$A$1:$F$2241,4,FALSE) -> 0 | N24: =VLOOKUP(A24,Marketing_df2!$A$1:$F$2241,5,FALSE) -> 2 | O24: =VLOOKUP(A24,Marketing_df2!$A$1:$F$2241,6,FALSE) -> 9
... A28: 26 | B28: 2404 | C28: 1976 | D28: Graduation | E28: Married | F28: 53359 | G28: 1 | H28: 1 | I28: =G28+H28 -> 2 | J28: 41421 | K28: 4 | L28: =VLOOKUP(A28,Marketing_df2!$A$1:$F$2241,3,FALSE) -> 4 | M28: =VLOOKUP(A28,Marketing_df2!$A$1:$F$2241,4,FALSE) -> 6 | N28: =VLOOKUP(A28,Marketing_df2!$A$1:$F$2241,5,FALSE) -> 5 | O28: =VLOOKUP(A28,Marketing_df2!$A$1:$F$2241,6,FALSE) -> 4
A29: 27 | B29: 5255 | C29: 1986 | D29: Graduation | E29: Single | G29: 1 | H29: 0 | I29: =G29+H29 -> 1 | J29: 41325 | K29: 19 | L29: =VLOOKUP(A29,Marketing_df2!$A$1:$F$2241,3,FALSE) -> 1 | M29: =VLOOKUP(A29,Marketing_df2!$A$1:$F$2241,4,FALSE) -> 263 | N29: =VLOOKUP(A29,Marketing_df2!$A$1:$F$2241,5,FALSE) -> 27 | O29: =VLOOKUP(A29,Marketing_df2!$A$1:$F$2241,6,FALSE) -> 0
A30: 28 | B30: 9422 | C30: 1989 | D30: Graduation | E30: Married | F30: 38360 | G30: 1 | H30: 0 | I30: =G30+H30 -> 1 | J30: 41425 | K30: 26 | L30: =VLOOKUP(A30,Marketing_df2!$A$1:$F$2241,3,FALSE) -> 2 | M30: =VLOOKUP(A30,Marketing_df2!$A$1:$F$2241,4,FALSE) -> 21 | N30: =VLOOKUP(A30,Marketing_df2!$A$1:$F$2241,5,FALSE) -> 2 | O30: =VLOOKUP(A30,Marketing_df2!$A$1:$F$2241,6,FALSE) -> 4
A31: 29 | B31: 1966 | C31: 1965 | D31: PhD | E31: Married | F31: 84618 | G31: 0 | H31: 0 | I31: =G31+H31 -> 0 | J31: 41600 | K31: 96 | L31: =VLOOKUP(A31,Marketing_df2!$A$1:$F$2241,3,FALSE) -> 100 | M31: =VLOOKUP(A31,Marketing_df2!$A$1:$F$2241,4,FALSE) -> 66 | N31: =VLOOKUP(A31,Marketing_df2!$A$1:$F$2241,5,FALSE) -> 6 | O31: =VLOOKUP(A31,Marketing_df2!$A$1:$F$2241,6,FALSE) -> 10
A32: 30 | B32: 6864 | C32: 1989 | D32: Master | E32: Divorced | F32: 10979 | G32: 0 | H32: 0 | I32: =G32+H32 -> 0 | J32: 41781 | K32: 34 | L32: =VLOOKUP(A32,Marketing_df2!$A$1:$F$2241,3,FALSE) -> 4 | M32: =VLOOKUP(A32,Marketing_df2!$A$1:$F$2241,4,FALSE) -> 2 | N32: =VLOOKUP(A32,Marketing_df2!$A$1:$F$2241,5,FALSE) -> 3 | O32: =VLOOKUP(A32,Marketing_df2!$A$1:$F$2241,6,FALSE) -> 3
A33: 31 | B33: 3033 | C33: 1963 | D33: Master | E33: Together | F33: 38620 | G33: 0 | H33: 0 | I33: =G33+H33 -> 0 | J33: 41405 | K33: 56 | L33: =VLOOKUP(A33,Marketing_df2!$A$1:$F$2241,3,FALSE) -> 17 | M33: =VLOOKUP(A33,Marketing_df2!$A$1:$F$2241,4,FALSE) -> 22 | N33: =VLOOKUP(A33,Marketing_df2!$A$1:$F$2241,5,FALSE) -> 2 | O33: =VLOOKUP(A33,Marketing_df2!$A$1:$F$2241,6,FALSE) -> 3
A34: 32 | B34: 5710 | C34: 1970 | D34: Graduation | E34: Together | F34: 40548 | G34: 0 | H34: 1 | I34: =G34+H34 -> 1 | J34: 41192 | K34: 31 | L34: =VLOOKUP(A34,Marketing_df2!$A$1:$F$2241,3,FALSE) -> 0 | M34: =VLOOKUP(A34,Marketing_df2!$A$1:$F$2241,4,FALSE) -> 0 | N34: =VLOOKUP(A34,Marketing_df2!$A$1:$F$2241,5,FALSE) -> 2 | O34: =VLOOKUP(A34,Marketing_df2!$A$1:$F$2241,6,FALSE) -> 4
A35: 33 | B35: 7373 | C35: 1952 | D35: PhD | E35: Divorced | F35: 46610 | G35: 0 | H35: 2 | I35: =G35+H35 -> 2 | J35: 41211 | K35: 8 | L35: =VLOOKUP(A35,Marketing_df2!$A$1:$F$2241,3,FALSE) -> 12 | M35: =VLOOKUP(A35,Marketing_df2!$A$1:$F$2241,4,FALSE) -> 22 | N35: =VLOOKUP(A35,Marketing_df2!$A$1:$F$2241,5,FALSE) -> 4 | O35: =VLOOKUP(A35,Marketing_df2!$A$1:$F$2241,6,FALSE) -> 6
A36: 34 | B36: 8755 | C36: 1946 | D36: Master | E36: Married | F36: 68657 | G36: 0 | H36: 0 | I36: =G36+H36 -> 0 | J36: 41325 | K36: 4 | L36: =VLOOKUP(A36,Marketing_df2!$A$1:$F$2241,3,FALSE) -> 34 | M36: =VLOOKUP(A36,Marketing_df2!$A$1:$F$2241,4,FALSE) -> 68 | N36: =VLOOKUP(A36,Marketing_df2!$A$1:$F$2241,5,FALSE) -> 3 | O36: =VLOOKUP(A36,Marketing_df2!$A$1:$F$2241,6,FALSE) -> 9
A37: 35 | B37: 10738 | C37: 1951 | D37: Master | E37: Single | F37: 49389 | G37: 1 | H37: 1 | I37: =G37+H37 -> 2 | J37: 41515 | K37: 55 | L37: =VLOOKUP(A37,Marketing_df2!$A$1:$F$2241,3,FALSE) -> 0 | M37: =VLOOKUP(A37,Marketing_df2!$A$1:$F$2241,4,FALSE) -> 1 | N37: =VLOOKUP(A37,Marketing_df2!$A$1:$F$2241,5,FALSE) -> 2 | O37: =VLOOKUP(A37,Marketing_df2!$A$1:$F$2241,6,FALSE) -> 3
A38: 36 | B38: 4339 | C38: 1970 | D38: PhD | E38: Married | F38: 67353 | G38: 0 | H38: 1 | I38: =G38+H38 -> 1 | J38: 41639 | K38: 37 | L38: =VLOOKUP(A38,Marketing_df2!$A$1:$F$2241,3,FALSE) -> 17 | M38: =VLOOKUP(A38,Marketing_df2!$A$1:$F$2241,4,FALSE) -> 8 | N38: =VLOOKUP(A38,Marketing_df2!$A$1:$F$2241,5,FALSE) -> 5 | O38: =VLOOKUP(A38,Marketing_df2!$A$1:$F$2241,6,FALSE) -> 12
A39: 37 | B39: 10755 | C39: 1976 | D39: 2n Cycle | E39: Married | F39: 23718 | G39: 1 | H39: 0 | I39: =G39+H39 -> 1 | J39: 41519 | K39: 76 | L39: =VLOOKUP(A39,Marketing_df2!$A$1:$F$2241,3,FALSE) -> 3 | M39: =VLOOKUP(A39,Marketing_df2!$A$1:$F$2241,4,FALSE) -> 7 | N39: =VLOOKUP(A39,Marketing_df2!$A$1:$F$2241,5,FALSE) -> 3 | O39: =VLOOKUP(A39,Marketing_df2!$A$1:$F$2241,6,FALSE) -> 2
A40: 38 | B40: 8595 | C40: 1973 | D40: Graduation | E40: Widow | F40: 42429 | G40: 0 | H40: 1 | I40: =G40+H40 -> 1 | J40: 41681 | K40: 99 | L40: =VLOOKUP(A40,Marketing_df2!$A$1:$F$2241,3,FALSE) -> 0 | M40: =VLOOKUP(A40,Marketing_df2!$A$1:$F$2241,4,FALSE) -> 0 | N40: =VLOOKUP(A40,Marketing_df2!$A$1:$F$2241,5,FALSE) -> 1 | O40: =VLOOKUP(A40,Marketing_df2!$A$1:$F$2241,6,FALSE) -> 3
A41: 39 | B41: 2968 | C41: 1943 | D41: PhD | E41: Divorced | F41: 48948 | G41: 0 | H41: 0 | I41: =G41+H41 -> 0 | J41: 41306 | K41: 53 | L41: =VLOOKUP(A41,Marketing_df2!$A$1:$F$2241,3,FALSE) -> 8 | M41: =VLOOKUP(A41,Marketing_df2!$A$1:$F$2241,4,FALSE) -> 49 | N41: =VLOOKUP(A41,Marketing_df2!$A$1:$F$2241,5,FALSE) -> 7 | O41: =VLOOKUP(A41,Marketing_df2!$A$1:$F$2241,6,FALSE) -> 5
... A44: 42 | B44: 8430 | C44: 1957 | D44: Graduation | E44: Together | F44: 21994 | G44: 0 | H44: 1 | I44: =G44+H44 -> 1 | J44: 41267 | K44: 4 | L44: =VLOOKUP(A44,Marketing_df2!$A$1:$F$2241,3,FALSE) -> 0 | M44: =VLOOKUP(A44,Marketing_df2!$A$1:$F$2241,4,FALSE) -> 1 | N44: =VLOOKUP(A44,Marketing_df2!$A$1:$F$2241,5,FALSE) -> 0 | O44: =VLOOKUP(A44,Marketing_df2!$A$1:$F$2241,6,FALSE) -> 3
A45: 43 | B45: 7281 | C45: 1959 | D45: PhD | E45: Single | G45: 0 | H45: 0 | I45: =G45+H45 -> 0 | J45: 41583 | K45: 80 | L45: =VLOOKUP(A45,Marketing_df2!$A$1:$F$2241,3,FALSE) -> 11 | M45: =VLOOKUP(A45,Marketing_df2!$A$1:$F$2241,4,FALSE) -> 2 | N45: =VLOOKUP(A45,Marketing_df2!$A$1:$F$2241,5,FALSE) -> 1 | O45: =VLOOKUP(A45,Marketing_df2!$A$1:$F$2241,6,FALSE) -> 4
...

Sheet Table
A1: Sl No. | B1: ID | C1: Year_Birth | D1: Age | E1: Education | F1: Marital_Status | G1: Income | H1: Income_Segment | I1: Kidhome | J1: Teenhome | K1: Total_Childrenhome | L1: Dt_Customer | M1: Tenure | N1: Recency | O1: MntFruits | P1: MntSweetProducts | Q1: MntTotal_Spent | R1: NumWebPurchases | S1: NumStorePurchases | T1: Total_Purchases
A2: 0 | B2: 5524 | C2: 1957 | D2: =2025-C2 -> 68 | E2: Graduation | F2: Single | G2: 58138 | H2: {=_xlfn.IFS( G2 < 25000, "Low", AND(G2 >= 25000, G2 < 75000), "Medium", AND(G2 >= 75000, G2 < 150000), "High", G2 >= 150000, "Very High" )} -> Medium | I2: 0 | J2: 0 | K2: =I2+J2 -> 0 | L2: 41156 | M2: =DATEDIF(L2, TODAY(), "Y") & " years, " & DATEDIF(L2, TODAY(), "YM") & " months" -> 13 years, 6 months | N2: 58 | O2: 88 | P2: 88 | Q2: =O2+P2 -> 176 | R2: 8 | S2: 4 | T2: =Table[[#This Row],[NumWebPurchases]]+Table[[#This Row],[NumStorePurchases]] -> 12
A3: 1 | B3: 2174 | C3: 1954 | D3: =2025-C3 -> 71 | E3: Graduation | F3: Single | G3: 46344 | H3: {=_xlfn.IFS( G3 < 25000, "Low", AND(G3 >= 25000, G3 < 75000), "Medium", AND(G3 >= 75000, G3 < 150000), "High", G3 >= 150000, "Very High" )} -> Medium | I3: 1 | J3: 1 | K3: =I3+J3 -> 2 | L3: 41706 | M3: =DATEDIF(L3, TODAY(), "Y") & " years, " & DATEDIF(L3, TODAY(), "YM") & " months" -> 11 years, 11 months | N3: 38 | O3: 1 | P3: 1 | Q3: =O3+P3 -> 2 | R3: 1 | S3: 2 | T3: =Table[[#This Row],[NumWebPurchases]]+Table[[#This Row],[NumStorePurchases]] -> 3
A4: 2 | B4: 4141 | C4: 1965 | D4: =2025-C4 -> 60 | E4: Graduation | F4: Together | G4: 71613 | H4: {=_xlfn.IFS( G4 < 25000, "Low", AND(G4 >= 25000, G4 < 75000), "Medium", AND(G4 >= 75000, G4 < 150000), "High", G4 >= 150000, "Very High" )} -> Medium | I4: 0 | J4: 0 | K4: =I4+J4 -> 0 | L4: 41507 | M4: =DATEDIF(L4, TODAY(), "Y") & " years, " & DATEDIF(L4, TODAY(), "YM") & " months" -> 12 years, 6 months | N4: 26 | O4: 49 | P4: 21 | Q4: =O4+P4 -> 70 | R4: 8 | S4: 10 | T4: =Table[[#This Row],[NumWebPurchases]]+Table[[#This Row],[NumStorePurchases]] -> 18
A5: 3 | B5: 6182 | C5: 1984 | D5: =2025-C5 -> 41 | E5: Graduation | F5: Together | G5: 26646 | H5: {=_xlfn.IFS( G5 < 25000, "Low", AND(G5 >= 25000, G5 < 75000), "Medium", AND(G5 >= 75000, G5 < 150000), "High", G5 >= 150000, "Very High" )} -> Medium | I5: 1 | J5: 0 | K5: =I5+J5 -> 1 | L5: 41680 | M5: =DATEDIF(L5, TODAY(), "Y") & " years, " & DATEDIF(L5, TODAY(), "YM") & " months" -> 12 years, 0 months | N5: 26 | O5: 4 | P5: 3 | Q5: =O5+P5 -> 7 | R5: 2 | S5: 4 | T5: =Table[[#This Row],[NumWebPurchases]]+Table[[#This Row],[NumStorePurchases]] -> 6
A6: 4 | B6: 5324 | C6: 1981 | D6: =2025-C6 -> 44 | E6: PhD | F6: Married | G6: 58293 | H6: {=_xlfn.IFS( G6 < 25000, "Low", AND(G6 >= 25000, G6 < 75000), "Medium", AND(G6 >= 75000, G6 < 150000), "High", G6 >= 150000, "Very High" )} -> Medium | I6: 1 | J6: 0 | K6: =I6+J6 -> 1 | L6: 41658 | M6: =DATEDIF(L6, TODAY(), "Y") & " years, " & DATEDIF(L6, TODAY(), "YM") & " months" -> 12 years, 1 months | N6: 94 | O6: 43 | P6: 27 | Q6: =O6+P6 -> 70 | R6: 5 | S6: 6 | T6: =Table[[#This Row],[NumWebPurchases]]+Table[[#This Row],[NumStorePurchases]] -> 11
A7: 5 | B7: 7446 | C7: 1967 | D7: =2025-C7 -> 58 | E7: Master | F7: Together | G7: 62513 | H7: {=_xlfn.IFS( G7 < 25000, "Low", AND(G7 >= 25000, G7 < 75000), "Medium", AND(G7 >= 75000, G7 < 150000), "High", G7 >= 150000, "Very High" )} -> Medium | I7: 0 | J7: 1 | K7: =I7+J7 -> 1 | L7: 41526 | M7: =DATEDIF(L7, TODAY(), "Y") & " years, " & DATEDIF(L7, TODAY(), "YM") & " months" -> 12 years, 5 months | N7: 16 | O7: 42 | P7: 42 | Q7: =O7+P7 -> 84 | R7: 6 | S7: 10 | T7: =Table[[#This Row],[NumWebPurchases]]+Table[[#This Row],[NumStorePurchases]] -> 16
A8: 6 | B8: 965 | C8: 1971 | D8: =2025-C8 -> 54 | E8: Graduation | F8: Divorced | G8: 55635 | H8: {=_xlfn.IFS( G8 < 25000, "Low", AND(G8 >= 25000, G8 < 75000), "Medium", AND(G8 >= 75000, G8 < 150000), "High", G8 >= 150000, "Very High" )} -> Medium | I8: 0 | J8: 1 | K8: =I8+J8 -> 1 | L8: 41226 | M8: =DATEDIF(L8, TODAY(), "Y") & " years, " & DATEDIF(L8, TODAY(), "YM") & " months" -> 13 years, 3 months | N8: 34 | O8: 65 | P8: 49 | Q8: =O8+P8 -> 114 | R8: 7 | S8: 7 | T8: =Table[[#This Row],[NumWebPurchases]]+Table[[#This Row],[NumStorePurchases]] -> 14
A9: 7 | B9: 6177 | C9: 1985 | D9: =2025-C9 -> 40 | E9: PhD | F9: Married | G9: 33454 | H9: {=_xlfn.IFS( G9 < 25000, "Low", AND(G9 >= 25000, G9 < 75000), "Medium", AND(G9 >= 75000, G9 < 150000), "High", G9 >= 150000, "Very High" )} -> Medium | I9: 1 | J9: 0 | K9: =I9+J9 -> 1 | L9: 41402 | M9: =DATEDIF(L9, TODAY(), "Y") & " years, " & DATEDIF(L9, TODAY(), "YM") & " months" -> 12 years, 9 months | N9: 32 | O9: 10 | P9: 1 | Q9: =O9+P9 -> 11 | R9: 4 | S9: 4 | T9: =Table[[#This Row],[NumWebPurchases]]+Table[[#This Row],[NumStorePurchases]] -> 8
A10: 8 | B10: 4855 | C10: 1974 | D10: =2025-C10 -> 51 | E10: PhD | F10: Together | G10: 30351 | H10: {=_xlfn.IFS( G10 < 25000, "Low", AND(G10 >= 25000, G10 < 75000), "Medium", AND(G10 >= 75000, G10 < 150000), "High", G10 >= 150000, "Very High" )} -> Medium | I10: 1 | J10: 0 | K10: =I10+J10 -> 1 | L10: 41431 | M10: =DATEDIF(L10, TODAY(), "Y") & " years, " & DATEDIF(L10, TODAY(), "YM") & " months" -> 12 years, 9 months | N10: 19 | O10: 0 | P10: 3 | Q10: =O10+P10 -> 3 | R10: 3 | S10: 2 | T10: =Table[[#This Row],[NumWebPurchases]]+Table[[#This Row],[NumStorePurchases]] -> 5
A11: 9 | B11: 5899 | C11: 1950 | D11: =2025-C11 -> 75 | E11: PhD | F11: Together | G11: 5648 | H11: {=_xlfn.IFS( G11 < 25000, "Low", AND(G11 >= 25000, G11 < 75000), "Medium", AND(G11 >= 75000, G11 < 150000), "High", G11 >= 150000, "Very High" )} -> Low | I11: 1 | J11: 1 | K11: =I11+J11 -> 2 | L11: 41711 | M11: =DATEDIF(L11, TODAY(), "Y") & " years, " & DATEDIF(L11, TODAY(), "YM") & " months" -> 11 years, 11 months | N11: 68 | O11: 0 | P11: 1 | Q11: =O11+P11 -> 1 | R11: 1 | S11: 0 | T11: =Table[[#This Row],[NumWebPurchases]]+Table[[#This Row],[NumStorePurchases]] -> 1
A12: 10 | B12: 1994 | C12: 1983 | D12: =2025-C12 -> 42 | E12: Graduation | F12: Married | G12: 51371 | H12: {=_xlfn.IFS( G12 < 25000, "Low", AND(G12 >= 25000, G12 < 75000), "Medium", AND(G12 >= 75000, G12 < 150000), "High", G12 >= 150000, "Very High" )} -> Medium | I12: 1 | J12: 0 | K12: =I12+J12 -> 1 | L12: 41593 | M12: =DATEDIF(L12, TODAY(), "Y") & " years, " & DATEDIF(L12, TODAY(), "YM") & " months" -> 12 years, 3 months | N12: 11 | O12: 5 | P12: 2 | Q12: =O12+P12 -> 7 | R12: 1 | S12: 2 | T12: =Table[[#This Row],[NumWebPurchases]]+Table[[#This Row],[NumStorePurchases]] -> 3
A13: 11 | B13: 387 | C13: 1976 | D13: =2025-C13 -> 49 | E13: Basic | F13: Married | G13: 7500 | H13: {=_xlfn.IFS( G13 < 25000, "Low", AND(G13 >= 25000, G13 < 75000), "Medium", AND(G13 >= 75000, G13 < 150000), "High", G13 >= 150000, "Very High" )} -> Low | I13: 0 | J13: 0 | K13: =I13+J13 -> 0 | L13: 41226 | M13: =DATEDIF(L13, TODAY(), "Y") & " years, " & DATEDIF(L13, TODAY(), "YM") & " months" -> 13 years, 3 months | N13: 59 | O13: 16 | P13: 1 | Q13: =O13+P13 -> 17 | R13: 2 | S13: 3 | T13: =Table[[#This Row],[NumWebPurchases]]+Table[[#This Row],[NumStorePurchases]] -> 5
... A2241: 2239 | B2241: 9405 | C2241: 1954 | D2241: =2025-C2241 -> 71 | E2241: PhD | F2241: Married | G2241: 52869 | H2241: {=_xlfn.IFS( G2241 < 25000, "Low", AND(G2241 >= 25000, G2241 < 75000), "Medium", AND(G2241 >= 75000, G2241 < 150000), "High", G2241 >= 150000, "Very High" )} -> Medium | I2241: 1 | J2241: 1 | K2241: =I2241+J2241 -> 2 | L2241: 41197 | M2241: =DATEDIF(L2241, TODAY(), "Y") & " years, " & DATEDIF(L2241, TODAY(), "YM") & " months" -> 13 years, 4 months | N2241: 40 | O2241: 3 | P2241: 1 | Q2241: =O2241+P2241 -> 4 | R2241: 3 | S2241: 4 | T2241: =Table[[#This Row],[NumWebPurchases]]+Table[[#This Row],[NumStorePurchases]] -> 7

Sheet KPIs
A1: Active Customers | B1: Purchase Volume | C1: Total Revenue | D1: Average Income | E1: Marital Status | F1: Customer Count | G1: Age Group | H1: Total Purchases | I1: Average Amount Spend | J1: Sum of NumWebPurchases | K1: Sum of NumStorePurchases | L1: % of Online Sales | M1: % of Offline Sales | N1: Avg. Recency (Days)
A2: 2240 | B2: 22120 | C2: 119538 | D2: 52237.863 | E2: Married | F2: 864 | G2: 69-78 | H2: 4209 | I2: 53.365179 | J2: 9150 | K2: 12970 | L2: =(GETPIVOTDATA("NumWebPurchases",$J$1)/GETPIVOTDATA("Total_Purchases",$B$1))*100 -> 41.36528 | M2: =(GETPIVOTDATA("NumStorePurchases",$K$1)/GETPIVOTDATA("Total_Purchases",$B$1))*100 -> 58.63472 | N2: 49.109375
E3: Grand Total | F3: 864 | G3: Grand Total | H3: 4209
A12: Purchases by Age Group
A14: Age Group | B14: Total Purchases
A15: 29-38 | B15: 1350
A16: 39-48 | B16: 4016
A17: 49-58 | B17: 6907
A18: 59-68 | B18: 5078
A19: 69-78 | B19: 4209
A20: 79-88 | B20: 545
A21: Grand Total | B21: 22105
A25: Total & Average Income by Age Group
A27: Age Group | B27: Total Income
A28: 29-38 | B28: 7158602
A29: 39-48 | B29: 21927977
A30: 49-58 | B30: 36267544
A31: 59-68 | B31: 26939072
A32: 69-78 | B32: 21982329
A33: 79-88 | B33: 2556935
A34: Grand Total | B34: 116832459
A37: Age Group | B37: Average Income
A38: 29-38 | B38: 48697.973
A39: 39-48 | B39: 47773.37
A40: 49-58 | B40: 50093.293
A41: 59-68 | B41: 55316.37
A42: 69-78 | B42: 57848.234
A43: 79-88 | B43: 63923.375
A44: Grand Total | B44: 52227.295
A49: Recency Count (Days) by Age Group
A51: Age Group | B51: Recency Count (Days)
A52: 29-38 | B52: 147
A53: 39-48 | B53: 459
A54: 49-58 | B54: 724
A55: 59-68 | B55: 487
A56: 69-78 | B56: 380
A57: 79-88 | B57: 40
A58: Grand Total | B58: 2237
A61: Customer Count by Marital Status
A63: Marital Status | B63: Customer Count
...
